Workbook
Name Slicer_Sector: #N/A

Sheet IndiaCPI_Inflation_Cleaned
A1: Sector | B1: Year | C1: Month | D1: Period | E1: Cereals and products | F1: Meat and fish | G1: Egg | H1: Milk and products | I1: Oils and fats | J1: Fruits | K1: Vegetables | L1: Pulses and products | M1: Sugar and Confectionery | N1: Spices | O1: Non-alcoholic beverages | P1: Prepared meals, snacks, sweets etc. | Q1: Food and beverages | R1: Pan, tobacco and intoxicants | S1: Clothing | T1: Footwear | U1: Clothing and footwear | V1: Housing | W1: Fuel and light | X1: Household goods and services | Y1: Health | Z1: Transport and communication | AA1: Recreation and amusement | AB1: Education | AC1: Personal care and effects | AD1: Miscellaneous | AE1: General index
A2: Rural | B2: 2013 | C2: January | D2: =_xlfn.CONCAT(LEFT(Table1[[#This Row],[Month]],3),"-",RIGHT(Table1[[#This Row],[Year]],2)) -> Jan-13 | E2: 107.5 | F2: 106.3 | G2: 108.1 | H2: 104.9 | I2: 106.1 | J2: 103.9 | K2: 101.9 | L2: 106.1 | M2: 106.8 | N2: 103.1 | O2: 104.8 | P2: 106.7 | Q2: 105.5 | R2: 105.1 | S2: 106.5 | T2: 105.8 | U2: 106.4 | V2: NA | W2: 105.5 | X2: 104.8 | Y2: 104 | Z2: 103.3 | AA2: 103.4 | AB2: 103.8 | AC2: 104.7 | AD2: 104 | AE2: 105.1
A3: Urban | B3: 2013 | C3: January | D3: =_xlfn.CONCAT(LEFT(Table1[[#This Row],[Month]],3),"-",RIGHT(Table1[[#This Row],[Year]],2)) -> Jan-13 | E3: 110.5 | F3: 109.1 | G3: 113 | H3: 103.6 | I3: 103.4 | J3: 102.3 | K3: 102.9 | L3: 105.8 | M3: 105.1 | N3: 101.8 | O3: 105.1 | P3: 107.9 | Q3: 105.9 | R3: 105.2 | S3: 105.9 | T3: 105 | U3: 105.8 | V3: 100.3 | W3: 105.4 | X3: 104.8 | Y3: 104.1 | Z3: 103.2 | AA3: 102.9 | AB3: 103.5 | AC3: 104.3 | AD3: 103.7 | AE3: 104
A4: Rural+Urban | B4: 2013 | C4: January | D4: =_xlfn.CONCAT(LEFT(Table1[[#This Row],[Month]],3),"-",RIGHT(Table1[[#This Row],[Year]],2)) -> Jan-13 | E4: 108.4 | F4: 107.3 | G4: 110 | H4: 104.4 | I4: 105.1 | J4: 103.2 | K4: 102.2 | L4: 106 | M4: 106.2 | N4: 102.7 | O4: 104.9 | P4: 107.3 | Q4: 105.6 | R4: 105.1 | S4: 106.3 | T4: 105.5 | U4: 106.2 | V4: 100.3 | W4: 105.5 | X4: 104.8 | Y4: 104 | Z4: 103.2 | AA4: 103.1 | AB4: 103.6 | AC4: 104.5 | AD4: 103.9 | AE4: 104.6
A5: Rural | B5: 2013 | C5: February | D5: =_xlfn.CONCAT(LEFT(Table1[[#This Row],[Month]],3),"-",RIGHT(Table1[[#This Row],[Year]],2)) -> Feb-13 | E5: 109.2 | F5: 108.7 | G5: 110.2 | H5: 105.4 | I5: 106.7 | J5: 104 | K5: 102.4 | L5: 105.9 | M5: 105.7 | N5: 103.1 | O5: 105.1 | P5: 107.7 | Q5: 106.3 | R5: 105.6 | S5: 107.1 | T5: 106.3 | U5: 107 | V5: NA | W5: 106.2 | X5: 105.2 | Y5: 104.4 | Z5: 103.9 | AA5: 104 | AB5: 104.1 | AC5: 104.6 | AD5: 104.4 | AE5: 105.8
A6: Urban | B6: 2013 | C6: February | D6: =_xlfn.CONCAT(LEFT(Table1[[#This Row],[Month]],3),"-",RIGHT(Table1[[#This Row],[Year]],2)) -> Feb-13 | E6: 112.9 | F6: 112.9 | G6: 116.9 | H6: 104 | I6: 103.5 | J6: 103.1 | K6: 104.9 | L6: 104.1 | M6: 103.8 | N6: 102.3 | O6: 106 | P6: 109 | Q6: 107.2 | R6: 106 | S6: 106.6 | T6: 105.5 | U6: 106.4 | V6: 100.4 | W6: 105.7 | X6: 105.2 | Y6: 104.7 | Z6: 104.4 | AA6: 103.3 | AB6: 103.7 | AC6: 104.3 | AD6: 104.3 | AE6: 104.7
A7: Rural+Urban | B7: 2013 | C7: February | D7: =_xlfn.CONCAT(LEFT(Table1[[#This Row],[Month]],3),"-",RIGHT(Table1[[#This Row],[Year]],2)) -> Feb-13 | E7: 110.4 | F7: 110.2 | G7: 112.8 | H7: 104.9 | I7: 105.5 | J7: 103.6 | K7: 103.2 | L7: 105.3 | M7: 105.1 | N7: 102.8 | O7: 105.5 | P7: 108.3 | Q7: 106.6 | R7: 105.7 | S7: 106.9 | T7: 106 | U7: 106.8 | V7: 100.4 | W7: 106 | X7: 105.2 | Y7: 104.5 | Z7: 104.2 | AA7: 103.6 | AB7: 103.9 | AC7: 104.5 | AD7: 104.4 | AE7: 105.3
A8: Rural | B8: 2013 | C8: March | D8: =_xlfn.CONCAT(LEFT(Table1[[#This Row],[Month]],3),"-",RIGHT(Table1[[#This Row],[Year]],2)) -> Mar-13 | E8: 110.2 | F8: 108.8 | G8: 109.9 | H8: 105.6 | I8: 106.2 | J8: 105.7 | K8: 101.4 | L8: 105.7 | M8: 105 | N8: 103.3 | O8: 105.6 | P8: 108.2 | Q8: 106.6 | R8: 106.5 | S8: 107.6 | T8: 106.8 | U8: 107.5 | V8: NA | W8: 106.1 | X8: 105.6 | Y8: 104.7 | Z8: 104.6 | AA8: 104 | AB8: 104.3 | AC8: 104.3 | AD8: 104.6 | AE8: 106
A9: Urban | B9: 2013 | C9: March | D9: =_xlfn.CONCAT(LEFT(Table1[[#This Row],[Month]],3),"-",RIGHT(Table1[[#This Row],[Year]],2)) -> Mar-13 | E9: 113.9 | F9: 111.4 | G9: 113.2 | H9: 104.3 | I9: 102.7 | J9: 104.9 | K9: 103.8 | L9: 103.5 | M9: 102.6 | N9: 102.4 | O9: 107 | P9: 109.8 | Q9: 107.3 | R9: 106.8 | S9: 107.2 | T9: 106 | U9: 107 | V9: 100.4 | W9: 106 | X9: 105.7 | Y9: 105.2 | Z9: 105.5 | AA9: 103.5 | AB9: 103.8 | AC9: 104.2 | AD9: 104.9 | AE9: 105
A10: Rural+Urban | B10: 2013 | C10: March | D10: =_xlfn.CONCAT(LEFT(Table1[[#This Row],[Month]],3),"-",RIGHT(Table1[[#This Row],[Year]],2)) -> Mar-13 | E10: 111.4 | F10: 109.7 | G10: 111.2 | H10: 105.1 | I10: 104.9 | J10: 105.3 | K10: 102.2 | L10: 105 | M10: 104.2 | N10: 103 | O10: 106.2 | P10: 108.9 | Q10: 106.9 | R10: 106.6 | S10: 107.4 | T10: 106.5 | U10: 107.3 | V10: 100.4 | W10: 106.1 | X10: 105.6 | Y10: 104.9 | Z10: 105.1 | AA10: 103.7 | AB10: 104 | AC10: 104.3 | AD10: 104.7 | AE10: 105.5
A11: Rural | B11: 2013 | C11: April | D11: =_xlfn.CONCAT(LEFT(Table1[[#This Row],[Month]],3),"-",RIGHT(Table1[[#This Row],[Year]],2)) -> Apr-13 | E11: 110.2 | F11: 109.5 | G11: 106.9 | H11: 106.3 | I11: 105.7 | J11: 108.3 | K11: 103.4 | L11: 105.7 | M11: 104.2 | N11: 103.2 | O11: 106.5 | P11: 108.8 | Q11: 107.1 | R11: 107.1 | S11: 108.1 | T11: 107.4 | U11: 108 | V11: NA | W11: 106.5 | X11: 106.1 | Y11: 105.1 | Z11: 104.4 | AA11: 104.5 | AB11: 104.8 | AC11: 102.7 | AD11: 104.6 | AE11: 106.4
A12: Urban | B12: 2013 | C12: April | D12: =_xlfn.CONCAT(LEFT(Table1[[#This Row],[Month]],3),"-",RIGHT(Table1[[#This Row],[Year]],2)) -> Apr-13 | E12: 114.6 | F12: 113.4 | G12: 106 | H12: 104.7 | I12: 102.1 | J12: 109.5 | K12: 109.7 | L12: 104.6 | M12: 102 | N12: 103.5 | O12: 108.2 | P12: 110.6 | Q12: 108.8 | R12: 108.5 | S12: 107.9 | T12: 106.4 | U12: 107.7 | V12: 100.5 | W12: 106.4 | X12: 106.5 | Y12: 105.7 | Z12: 105 | AA12: 104 | AB12: 105.2 | AC12: 103.2 | AD12: 105.1 | AE12: 105.7
A13: Rural+Urban | B13: 2013 | C13: April | D13: =_xlfn.CONCAT(LEFT(Table1[[#This Row],[Month]],3),"-",RIGHT(Table1[[#This Row],[Year]],2)) -> Apr-13 | E13: 111.6 | F13: 110.9 | G13: 106.6 | H13: 105.7 | I13: 104.4 | J13: 108.9 | K13: 105.5 | L13: 105.3 | M13: 103.5 | N13: 103.3 | O13: 107.2 | P13: 109.6 | Q13: 107.7 | R13: 107.5 | S13: 108 | T13: 107 | U13: 107.9 | V13: 100.5 | W13: 106.5 | X13: 106.3 | Y13: 105.3 | Z13: 104.7 | AA13: 104.2 | AB13: 105 | AC13: 102.9 | AD13: 104.8 | AE13: 106.1
A14: Rural | B14: 2013 | C14: May | D14: =_xlfn.CONCAT(LEFT(Table1[[#This Row],[Month]],3),"-",RIGHT(Table1[[#This Row],[Year]],2)) -> May-13 | E14: 110.9 | F14: 109.8 | G14: 105.9 | H14: 107.5 | I14: 105.3 | J14: 108.1 | K14: 107.3 | L14: 106.1 | M14: 103.7 | N14: 104 | O14: 107.4 | P14: 109.9 | Q14: 108.1 | R14: 108.1 | S14: 108.8 | T14: 107.9 | U14: 108.6 | V14: NA | W14: 107.5 | X14: 106.8 | Y14: 105.7 | Z14: 104.1 | AA14: 105 | AB14: 105.5 | AC14: 102.1 | AD14: 104.8 | AE14: 107.2
A15: Urban | B15: 2013 | C15: May | D15: =_xlfn.CONCAT(LEFT(Table1[[#This Row],[Month]],3),"-",RIGHT(Table1[[#This Row],[Year]],2)) -> May-13 | E15: 115.4 | F15: 114.2 | G15: 102.7 | H15: 105.5 | I15: 101.5 | J15: 110.6 | K15: 123.7 | L15: 105.2 | M15: 101.9 | N15: 105 | O15: 109.1 | P15: 111.3 | Q15: 111.1 | R15: 109.8 | S15: 108.5 | T15: 106.7 | U15: 108.3 | V15: 100.5 | W15: 107.2 | X15: 107.1 | Y15: 106.2 | Z15: 103.9 | AA15: 104.6 | AB15: 105.7 | AC15: 102.6 | AD15: 104.9 | AE15: 106.6
A16: Rural+Urban | B16: 2013 | C16: May | D16: =_xlfn.CONCAT(LEFT(Table1[[#This Row],[Month]],3),"-",RIGHT(Table1[[#This Row],[Year]],2)) -> May-13 | E16: 112.3 | F16: 111.3 | G16: 104.7 | H16: 106.8 | I16: 103.9 | J16: 109.3 | K16: 112.9 | L16: 105.8 | M16: 103.1 | N16: 104.3 | O16: 108.1 | P16: 110.5 | Q16: 109.2 | R16: 108.6 | S16: 108.7 | T16: 107.4 | U16: 108.5 | V16: 100.5 | W16: 107.4 | X16: 106.9 | Y16: 105.9 | Z16: 104 | AA16: 104.8 | AB16: 105.6 | AC16: 102.3 | AD16: 104.8 | AE16: 106.9
A17: Rural | B17: 2013 | C17: June | D17: =_xlfn.CONCAT(LEFT(Table1[[#This Row],[Month]],3),"-",RIGHT(Table1[[#This Row],[Year]],2)) -> Jun-13 | E17: 112.3 | F17: 112.1 | G17: 108.1 | H17: 108.3 | I17: 105.9 | J17: 109.2 | K17: 118 | L17: 106.8 | M17: 104.1 | N17: 105.4 | O17: 108.2 | P17: 111 | Q17: 110.6 | R17: 109 | S17: 109.7 | T17: 108.8 | U17: 109.5 | V17: NA | W17: 108.5 | X17: 107.5 | Y17: 106.3 | Z17: 105 | AA17: 105.6 | AB17: 106.5 | AC17: 102.5 | AD17: 105.5 | AE17: 108.9
A18: Urban | B18: 2013 | C18: June | D18: =_xlfn.CONCAT(LEFT(Table1[[#This Row],[Month]],3),"-",RIGHT(Table1[[#This Row],[Year]],2)) -> Jun-13 | E18: 117 | F18: 120.1 | G18: 112.5 | H18: 107.3 | I18: 101.3 | J18: 112.4 | K18: 143.6 | L18: 105.4 | M18: 101.4 | N18: 106.4 | O18: 110 | P18: 112.2 | Q18: 115 | R18: 110.9 | S18: 109.2 | T18: 107.2 | U18: 108.9 | V18: 106.6 | W18: 108 | X18: 107.7 | Y18: 106.5 | Z18: 105.2 | AA18: 105.2 | AB18: 108.1 | AC18: 103.3 | AD18: 106.1 | AE18: 109.7
A19: Rural+Urban | B19: 2013 | C19: June | D19: =_xlfn.CONCAT(LEFT(Table1[[#This Row],[Month]],3),"-",RIGHT(Table1[[#This Row],[Year]],2)) -> Jun-13 | E19: 113.8 | F19: 114.9 | G19: 109.8 | H19: 107.9 | I19: 104.2 | J19: 110.7 | K19: 126.7 | L19: 106.3 | M19: 103.2 | N19: 105.7 | O19: 109 | P19: 111.6 | Q19: 112.2 | R19: 109.5 | S19: 109.5 | T19: 108.1 | U19: 109.3 | V19: 106.6 | W19: 108.3 | X19: 107.6 | Y19: 106.4 | Z19: 105.1 | AA19: 105.4 | AB19: 107.4 | AC19: 102.8 | AD19: 105.8 | AE19: 109.3
A20: Rural | B20: 2013 | C20: July | D20: =_xlfn.CONCAT(LEFT(Table1[[#This Row],[Month]],3),"-",RIGHT(Table1[[#This Row],[Year]],2)) -> Jul-13 | E20: 113.4 | F20: 114.9 | G20: 110.5 | H20: 109.3 | I20: 106.2 | J20: 110.3 | K20: 129.2 | L20: 107.1 | M20: 104.3 | N20: 106.4 | O20: 109.1 | P20: 112.1 | Q20: 113.1 | R20: 109.8 | S20: 110.5 | T20: 109.5 | U20: 110.3 | V20: NA | W20: 109.5 | X20: 108.3 | Y20: 106.9 | Z20: 106.8 | AA20: 106.4 | AB20: 107.8 | AC20: 102.5 | AD20: 106.5 | AE20: 110.7
A21: Urban | B21: 2013 | C21: July | D21: =_xlfn.CONCAT(LEFT(Table1[[#This Row],[Month]],3),"-",RIGHT(Table1[[#This Row],[Year]],2)) -> Jul-13 | E21: 117.8 | F21: 119.2 | G21: 114 | H21: 108.3 | I21: 101.1 | J21: 113.2 | K21: 160.9 | L21: 105.1 | M21: 101.3 | N21: 107.5 | O21: 110.4 | P21: 113.1 | Q21: 117.5 | R21: 111.7 | S21: 109.8 | T21: 107.8 | U21: 109.5 | V21: 107.7 | W21: 108.6 | X21: 108.1 | Y21: 107.1 | Z21: 107.3 | AA21: 105.9 | AB21: 110.1 | AC21: 103.2 | AD21: 107.3 | AE21: 111.4
A22: Rural+Urban | B22: 2013 | C22: July | D22: =_xlfn.CONCAT(LEFT(Table1[[#This Row],[Month]],3),"-",RIGHT(Table1[[#This Row],[Year]],2)) -> Jul-13 | E22: 114.8 | F22: 116.4 | G22: 111.9 | H22: 108.9 | I22: 104.3 | J22: 111.7 | K22: 140 | L22: 106.4 | M22: 103.3 | N22: 106.8 | O22: 109.6 | P22: 112.6 | Q22: 114.7 | R22: 110.3 | S22: 110.2 | T22: 108.8 | U22: 110 | V22: 107.7 | W22: 109.2 | X22: 108.2 | Y22: 107 | Z22: 107.1 | AA22: 106.1 | AB22: 109.1 | AC22: 102.8 | AD22: 106.9 | AE22: 111
A23: Rural | B23: 2013 | C23: August | D23: =_xlfn.CONCAT(LEFT(Table1[[#This Row],[Month]],3),"-",RIGHT(Table1[[#This Row],[Year]],2)) -> Aug-13 | E23: 114.3 | F23: 115.4 | G23: 111.1 | H23: 110 | I23: 106.4 | J23: 110.8 | K23: 138.9 | L23: 107.4 | M23: 104.1 | N23: 106.9 | O23: 109.7 | P23: 112.6 | Q23: 114.9 | R23: 110.7 | S23: 111.3 | T23: 110.2 | U23: 111.1 | V23: NA | W23: 109.9 | X23: 108.7 | Y23: 107.5 | Z23: 107.8 | AA23: 106.8 | AB23: 108.7 | AC23: 105 | AD23: 107.5 | AE23: 112.1
A24: Urban | B24: 2013 | C24: August | D24: =_xlfn.CONCAT(LEFT(Table1[[#This Row],[Month]],3),"-",RIGHT(Table1[[#This Row],[Year]],2)) -> Aug-13 | E24: 118.3 | F24: 120.4 | G24: 112.7 | H24: 108.9 | I24: 101.1 | J24: 108.7 | K24: 177 | L24: 104.7 | M24: 101 | N24: 108.5 | O24: 110.9 | P24: 114.3 | Q24: 119.6 | R24: 112.4 | S24: 110.6 | T24: 108.3 | U24: 110.2 | V24: 108.9 | W24: 109.3 | X24: 108.7 | Y24: 107.6 | Z24: 108.1 | AA24: 106.5 | AB24: 110.8 | AC24: 106 | AD24: 108.3 | AE24: 112.7
A25: Rural+Urban | B25: 2013 | C25: August | D25: =_xlfn.CONCAT(LEFT(Table1[[#This Row],[Month]],3),"-",RIGHT(Table1[[#This Row],[Year]],2)) -> Aug-13 | E25: 115.6 | F25: 117.2 | G25: 111.7 | H25: 109.6 | I25: 104.5 | J25: 109.8 | K25: 151.8 | L25: 106.5 | M25: 103.1 | N25: 107.4 | O25: 110.2 | P25: 113.4 | Q25: 116.6 | R25: 111.2 | S25: 111 | T25: 109.4 | U25: 110.7 | V25: 108.9 | W25: 109.7 | X25: 108.7 | Y25: 107.5 | Z25: 108 | AA25: 106.6 | AB25: 109.9 | AC25: 105.4 | AD25: 107.9 | AE25: 112.4
A26: Rural | B26: 2013 | C26: September | D26: =_xlfn.CONCAT(LEFT(Table1[[#This Row],[Month]],3),"-",RIGHT(Table1[[#This Row],[Year]],2)) -> Sep-13 | E26: 115.4 | F26: 115.7 | G26: 111.7 | H26: 111 | I26: 107.4 | J26: 110.9 | K26: 154 | L26: 108.1 | M26: 104.2 | N26: 107.9 | O26: 110.4 | P26: 114 | Q26: 117.8 | R26: 111.7 | S26: 112.7 | T26: 111.4 | U26: 112.5 | V26: NA | W26: 111.1 | X26: 109.6 | Y26: 108.3 | Z26: 109.3 | AA26: 107.7 | AB26: 109.8 | AC26: 106.7 | AD26: 108.7 | AE26: 114.2
A27: Urban | B27: 2013 | C27: September | D27: =_xlfn.CONCAT(LEFT(Table1[[#This Row],[Month]],3),"-",RIGHT(Table1[[#This Row],[Year]],2)) -> Sep-13 | E27: 118.6 | F27: 119.1 | G27: 113.2 | H27: 109.6 | I27: 101.7 | J27: 103.2 | K27: 174.3 | L27: 105.1 | M27: 100.8 | N27: 109.1 | O27: 111.1 | P27: 115.4 | Q27: 119.2 | R27: 112.9 | S27: 111.4 | T27: 109 | U27: 111.1 | V27: 109.7 | W27: 109.5 | X27: 109.6 | Y27: 107.9 | Z27: 110.4 | AA27: 107.4 | AB27: 111.2 | AC27: 106.9 | AD27: 109.4 | AE27: 113.2
A28: Rural+Urban | B28: 2013 | C28: September | D28: =_xlfn.CONCAT(LEFT(Table1[[#This Row],[Month]],3),"-",RIGHT(Table1[[#This Row],[Year]],2)) -> Sep-13 | E28: 116.4 | F28: 116.9 | G28: 112.3 | H28: 110.5 | I28: 105.3 | J28: 107.3 | K28: 160.9 | L28: 107.1 | M28: 103.1 | N28: 108.3 | O28: 110.7 | P28: 114.6 | Q28: 118.3 | R28: 112 | S28: 112.2 | T28: 110.4 | U28: 111.9 | V28: 109.7 | W28: 110.5 | X28: 109.6 | Y28: 108.1 | Z28: 109.9 | AA28: 107.5 | AB28: 110.6 | AC28: 106.8 | AD28: 109 | AE28: 113.7
A29: Rural | B29: 2013 | C29: October | D29: =_xlfn.CONCAT(LEFT(Table1[[#This Row],[Month]],3),"-",RIGHT(Table1[[#This Row],[Year]],2)) -> Oct-13 | E29: 116.3 | F29: 115.4 | G29: 112.6 | H29: 111.7 | I29: 107.7 | J29: 113.2 | K29: 164.9 | L29: 108.3 | M29: 103.9 | N29: 108.2 | O29: 111.1 | P29: 114.9 | Q29: 119.8 | R29: 112.2 | S29: 113.6 | T29: 112.3 | U29: 113.4 | V29: NA | W29: 111.6 | X29: 110.4 | Y29: 108.9 | Z29: 109.3 | AA29: 108.3 | AB29: 110.2 | AC29: 107.5 | AD29: 109.1 | AE29: 115.5
A30: Urban | B30: 2013 | C30: October | D30: =_xlfn.CONCAT(LEFT(Table1[[#This Row],[Month]],3),"-",RIGHT(Table1[[#This Row],[Year]],2)) -> Oct-13 | E30: 118.9 | F30: 118.1 | G30: 114.5 | H30: 110.4 | I30: 102.3 | J30: 106.2 | K30: 183.5 | L30: 105.3 | M30: 100.2 | N30: 109.6 | O30: 111.4 | P30: 116 | Q30: 120.8 | R30: 113.5 | S30: 112.5 | T30: 109.7 | U30: 112 | V30: 110.5 | W30: 109.7 | X30: 110.2 | Y30: 108.2 | Z30: 109.7 | AA30: 108 | AB30: 111.3 | AC30: 107.3 | AD30: 109.4 | AE30: 114
A31: Rural+Urban | B31: 2013 | C31: October | D31: =_xlfn.CONCAT(LEFT(Table1[[#This Row],[Month]],3),"-",RIGHT(Table1[[#This Row],[Year]],2)) -> Oct-13 | E31: 117.1 | F31: 116.3 | G31: 113.3 | H31: 111.2 | I31: 105.7 | J31: 109.9 | K31: 171.2 | L31: 107.3 | M31: 102.7 | N31: 108.7 | O31: 111.2 | P31: 115.4 | Q31: 120.2 | R31: 112.5 | S31: 113.2 | T31: 111.2 | U31: 112.8 | V31: 110.5 | W31: 110.9 | X31: 110.3 | Y31: 108.6 | Z31: 109.5 | AA31: 108.1 | AB31: 110.8 | AC31: 107.4 | AD31: 109.2 | AE31: 114.8
A32: Rural | B32: 2013 | C32: November | D32: =_xlfn.CONCAT(LEFT(Table1[[#This Row],[Month]],3),"-",RIGHT(Table1[[#This Row],[Year]],2)) -> Nov-13 | E32: 117.3 | F32: 114.9 | G32: 116.2 | H32: 112.8 | I32: 108.9 | J32: 116.6 | K32: 178.1 | L32: 109.1 | M32: 103.6 | N32: 109 | O32: 111.8 | P32: 116 | Q32: 122.5 | R32: 112.8 | S32: 114.6 | T32: 113.1 | U32: 114.4 | V32: NA | W32: 112.6 | X32: 111.3 | Y32: 109.7 | Z32: 109.6 | AA32: 108.7 | AB32: 111 | AC32: 108.2 | AD32: 109.8 | AE32: 117.4
A33: Urban | B33: 2013 | C33: November | D33: =_xlfn.CONCAT(LEFT(Table1[[#This Row],[Month]],3),"-",RIGHT(Table1[[#This Row],[Year]],2)) -> Nov-13 | E33: 119.8 | F33: 116.3 | G33: 122.6 | H33: 112 | I33: 103.2 | J33: 110 | K33: 192.8 | L33: 106.3 | M33: 99.5 | N33: 110.3 | O33: 111.8 | P33: 117.1 | Q33: 122.9 | R33: 114.1 | S33: 113.5 | T33: 110.3 | U33: 113 | V33: 111.1 | W33: 110 | X33: 110.9 | Y33: 108.6 | Z33: 109.5 | AA33: 108.5 | AB33: 111.3 | AC33: 107.9 | AD33: 109.6 | AE33: 115
A34: Rural+Urban | B34: 2013 | C34: November | D34: =_xlfn.CONCAT(LEFT(Table1[[#This Row],[Month]],3),"-",RIGHT(Table1[[#This Row],[Year]],2)) -> Nov-13 | E34: 118.1 | F34: 115.4 | G34: 118.7 | H34: 112.5 | I34: 106.8 | J34: 113.5 | K34: 183.1 | L34: 108.2 | M34: 102.2 | N34: 109.4 | O34: 111.8 | P34: 116.5 | Q34: 122.6 | R34: 113.1 | S34: 114.2 | T34: 111.9 | U34: 113.8 | V34: 111.1 | W34: 111.6 | X34: 111.1 | Y34: 109.3 | Z34: 109.5 | AA34: 108.6 | AB34: 111.2 | AC34: 108.1 | AD34: 109.7 | AE34: 116.3
A35: Rural | B35: 2013 | C35: December | D35: =_xlfn.CONCAT(LEFT(Table1[[#This Row],[Month]],3),"-",RIGHT(Table1[[#This Row],[Year]],2)) -> Dec-13 | E35: 118.4 | F35: 115.9 | G35: 120.4 | H35: 113.8 | I35: 109.5 | J35: 115.5 | K35: 145.7 | L35: 109.5 | M35: 102.9 | N35: 109.8 | O35: 112.1 | P35: 116.8 | Q35: 118.7 | R35: 113.6 | S35: 115.8 | T35: 114 | U35: 115.5 | V35: NA | W35: 112.8 | X35: 112.1 | Y35: 110.1 | Z35: 109.9 | AA35: 109.2 | AB35: 111.6 | AC35: 108.1 | AD35: 110.1 | AE35: 115.5
A36: Urban | B36: 2013 | C36: December | D36: =_xlfn.CONCAT(LEFT(Table1[[#This Row],[Month]],3),"-",RIGHT(Table1[[#This Row],[Year]],2)) -> Dec-13 | E36: 120.5 | F36: 118.1 | G36: 128.5 | H36: 112.8 | I36: 103.4 | J36: 110.7 | K36: 144.8 | L36: 107.1 | M36: 98.6 | N36: 111.9 | O36: 112.1 | P36: 118.1 | Q36: 117.8 | R36: 115 | S36: 114.2 | T36: 110.9 | U36: 113.7 | V36: 110.7 | W36: 110.4 | X36: 111.3 | Y36: 109 | Z36: 109.7 | AA36: 108.9 | AB36: 111.4 | AC36: 107.7 | AD36: 109.8 | AE36: 113.3
A37: Rural+Urban | B37: 2013 | C37: December | D37: =_xlfn.CONCAT(LEFT(Table1[[#This Row],[Month]],3),"-",RIGHT(Table1[[#This Row],[Year]],2)) -> Dec-13 | E37: 119.1 | F37: 116.7 | G37: 123.5 | H37: 113.4 | I37: 107.3 | J37: 113.3 | K37: 145.4 | L37: 108.7 | M37: 101.5 | N37: 110.5 | O37: 112.1 | P37: 117.4 | Q37: 118.4 | R37: 114 | S37: 115.2 | T37: 112.7 | U37: 114.8 | V37: 110.7 | W37: 111.9 | X37: 111.7 | Y37: 109.7 | Z37: 109.8 | AA37: 109 | AB37: 111.5 | AC37: 107.9 | AD37: 110 | AE37: 114.5
A38: Rural | B38: 2014 | C38: January | D38: =_xlfn.CONCAT(LEFT(Table1[[#This Row],[Month]],3),"-",RIGHT(Table1[[#This Row],[Year]],2)) -> Jan-14 | E38: 118.9 | F38: 117.1 | G38: 120.5 | H38: 114.4 | I38: 109 | J38: 115.5 | K38: 123.9 | L38: 109.6 | M38: 101.8 | N38: 110.2 | O38: 112.4 | P38: 117.3 | Q38: 116 | R38: 114 | S38: 116.5 | T38: 114.5 | U38: 116.2 | V38: NA | W38: 113 | X38: 112.6 | Y38: 110.6 | Z38: 110.5 | AA38: 109.6 | AB38: 111.8 | AC38: 108.3 | AD38: 110.6 | AE38: 114.2
A39: Urban | B39: 2014 | C39: January | D39: =_xlfn.CONCAT(LEFT(Table1[[#This Row],[Month]],3),"-",RIGHT(Table1[[#This Row],[Year]],2)) -> Jan-14 | E39: 121.2 | F39: 122 | G39: 129.9 | H39: 113.6 | I39: 102.9 | J39: 112.1 | K39: 118.9 | L39: 107.5 | M39: 96.9 | N39: 112.7 | O39: 112.1 | P39: 119 | Q39: 115.5 | R39: 115.7 | S39: 114.8 | T39: 111.3 | U39: 114.3 | V39: 111.6 | W39: 111 | X39: 111.9 | Y39: 109.7 | Z39: 110.8 | AA39: 109.8 | AB39: 111.5 | AC39: 108 | AD39: 110.5 | AE39: 112.9
A40: Rural+Urban | B40: 2014 | C40: January | D40: =_xlfn.CONCAT(LEFT(Table1[[#This Row],[Month]],3),"-",RIGHT(Table1[[#This Row],[Year]],2)) -> Jan-14 | E40: 119.6 | F40: 118.8 | G40: 124.1 | H40: 114.1 | I40: 106.8 | J40: 113.9 | K40: 122.2 | L40: 108.9 | M40: 100.2 | N40: 111 | O40: 112.3 | P40: 118.1 | Q40: 115.8 | R40: 114.5 | S40: 115.8 | T40: 113.2 | U40: 115.4 | V40: 111.6 | W40: 112.2 | X40: 112.3 | Y40: 110.3 | Z40: 110.7 | AA40: 109.7 | AB40: 111.6 | AC40: 108.2 | AD40: 110.6 | AE40: 113.6
...

Sheet Data_Structured&Imputed
A1: Year | B1: Month | C1: Period | D1: Attribute | E1: Rural | F1: Rural+Urban | G1: Urban | H1: Category
A2: 2013 | B2: April | C2: Apr-13 | D2: Cereals and products | E2: 110.2 | F2: 111.6 | G2: 114.6 | H2: Food & Beverages
A3: 2013 | B3: August | C3: Aug-13 | D3: Cereals and products | E3: 114.3 | F3: 115.6 | G3: 118.3 | H3: Food & Beverages
A4: 2013 | B4: April | C4: Apr-13 | D4: Clothing | E4: 108.1 | F4: 108 | G4: 107.9 | H4: Apparel
A5: 2013 | B5: April | C5: Apr-13 | D5: Meat and fish | E5: 109.5 | F5: 110.9 | G5: 113.4 | H5: Food & Beverages
A6: 2013 | B6: April | C6: Apr-13 | D6: Clothing and footwear | E6: 108 | F6: 107.9 | G6: 107.7 | H6: Apparel
A7: 2013 | B7: April | C7: Apr-13 | D7: Egg | E7: 106.9 | F7: 106.6 | G7: 106 | H7: Food & Beverages
A8: 2013 | B8: April | C8: Apr-13 | D8: Education | E8: 104.8 | F8: 105 | G8: 105.2 | H8: Education
A9: 2013 | B9: April | C9: Apr-13 | D9: Milk and products | E9: 106.3 | F9: 105.7 | G9: 104.7 | H9: Food & Beverages
A10: 2013 | B10: April | C10: Apr-13 | D10: Oils and fats | E10: 105.7 | F10: 104.4 | G10: 102.1 | H10: Food & Beverages
A11: 2013 | B11: April | C11: Apr-13 | D11: Food and beverages | E11: 107.1 | F11: 107.7 | G11: 108.8 | H11: Food & Beverages
A12: 2013 | B12: April | C12: Apr-13 | D12: Fruits | E12: 108.3 | F12: 108.9 | G12: 109.5 | H12: Food & Beverages
A13: 2013 | B13: April | C13: Apr-13 | D13: Footwear | E13: 107.4 | F13: 107 | G13: 106.4 | H13: Apparel
... A2243: 2020 | B2243: April | C2243: Apr-20 | D2243: Cereals and products | E2243: 147.2 | F2243: 148.7 | G2243: 151.8 | H2243: Food & Beverages
A2244: 2020 | B2244: April | C2244: Apr-20 | D2244: Clothing | E2244: =VLOOKUP(CPI_Inflation_Data_Structured[[#This Row],[Attribute]],'Moving Average'!$A$4:$D$32,2,0) -> 153.06667 | F2244: =VLOOKUP(CPI_Inflation_Data_Structured[[#This Row],[Attribute]],'Moving Average'!$A$4:$D$32,3,0) -> 150.83333 | G2244: =VLOOKUP(CPI_Inflation_Data_Structured[[#This Row],[Attribute]],'Moving Average'!$A$4:$D$32,4,0) -> 147.33333 | H2244: Apparel
A2245: 2020 | B2245: April | C2245: Apr-20 | D2245: Clothing and footwear | E2245: =VLOOKUP(CPI_Inflation_Data_Structured[[#This Row],[Attribute]],'Moving Average'!$A$4:$D$32,2,0) -> 152.3 | F2245: =VLOOKUP(CPI_Inflation_Data_Structured[[#This Row],[Attribute]],'Moving Average'!$A$4:$D$32,3,0) -> 149.5 | G2245: =VLOOKUP(CPI_Inflation_Data_Structured[[#This Row],[Attribute]],'Moving Average'!$A$4:$D$32,4,0) -> 145.23333 | H2245: Apparel
A2246: 2020 | B2246: April | C2246: Apr-20 | D2246: Education | E2246: =VLOOKUP(CPI_Inflation_Data_Structured[[#This Row],[Attribute]],'Moving Average'!$A$4:$D$32,2,0) -> 161.6 | F2246: =VLOOKUP(CPI_Inflation_Data_Structured[[#This Row],[Attribute]],'Moving Average'!$A$4:$D$32,3,0) -> 156.13333 | G2246: =VLOOKUP(CPI_Inflation_Data_Structured[[#This Row],[Attribute]],'Moving Average'!$A$4:$D$32,4,0) -> 152.26667 | H2246: Education
A2247: 2020 | B2247: April | C2247: Apr-20 | D2247: Egg | E2247: 146.9 | F2247: 148.8 | G2247: 151.9 | H2247: Food & Beverages
A2248: 2020 | B2248: April | C2248: Apr-20 | D2248: Food and beverages | E2248: 150.1 | F2248: 151.4 | G2248: 153.5 | H2248: Food & Beverages
A2249: 2020 | B2249: April | C2249: Apr-20 | D2249: Footwear | E2249: =VLOOKUP(CPI_Inflation_Data_Structured[[#This Row],[Attribute]],'Moving Average'!$A$4:$D$32,2,0) -> 147.5 | F2249: =VLOOKUP(CPI_Inflation_Data_Structured[[#This Row],[Attribute]],'Moving Average'!$A$4:$D$32,3,0) -> 141.7 | G2249: =VLOOKUP(CPI_Inflation_Data_Structured[[#This Row],[Attribute]],'Moving Average'!$A$4:$D$32,4,0) -> 133.5 | H2249: Apparel
A2250: 2020 | B2250: April | C2250: Apr-20 | D2250: Fruits | E2250: 147.3 | F2250: 149.9 | G2250: 152.9 | H2250: Food & Beverages
A2251: 2020 | B2251: April | C2251: Apr-20 | D2251: Fuel and light | E2251: 148.4 | F2251: 144.1 | G2251: 137.1 | H2251: Energy
A2252: 2020 | B2252: April | C2252: Apr-20 | D2252: General index | E2252: =VLOOKUP(CPI_Inflation_Data_Structured[[#This Row],[Attribute]],'Moving Average'!$A$4:$D$32,2,0) -> 150.7 | F2252: =VLOOKUP(CPI_Inflation_Data_Structured[[#This Row],[Attribute]],'Moving Average'!$A$4:$D$32,3,0) -> 149.3 | G2252: =VLOOKUP(CPI_Inflation_Data_Structured[[#This Row],[Attribute]],'Moving Average'!$A$4:$D$32,4,0) -> 147.73333 | H2252: General Index
A2253: 2020 | B2253: April | C2253: Apr-20 | D2253: Health | E2253: 154.3 | F2253: 150.7 | G2253: 144.8 | H2253: Health
A2254: 2020 | B2254: April | C2254: Apr-20 | D2254: Household goods and services | E2254: =VLOOKUP(CPI_Inflation_Data_Structured[[#This Row],[Attribute]],'Moving Average'!$A$4:$D$32,2,0) -> 151.66667 | F2254: =VLOOKUP(CPI_Inflation_Data_Structured[[#This Row],[Attribute]],'Moving Average'!$A$4:$D$32,3,0) -> 146.33333 | G2254: =VLOOKUP(CPI_Inflation_Data_Structured[[#This Row],[Attribute]],'Moving Average'!$A$4:$D$32,4,0) -> 140.43333 | H2254: Housing
A2255: 2020 | B2255: April | C2255: Apr-20 | D2255: Housing | E2255: 0 | F2255: 155.6 | G2255: 155.6 | H2255: Housing
A2256: 2020 | B2256: April | C2256: Apr-20 | D2256: Meat and fish | E2256: =VLOOKUP(CPI_Inflation_Data_Structured[[#This Row],[Attribute]],'Moving Average'!$A$4:$D$32,2,0) -> 167.2 | F2256: =VLOOKUP(CPI_Inflation_Data_Structured[[#This Row],[Attribute]],'Moving Average'!$A$4:$D$32,3,0) -> 167.3 | G2256: =VLOOKUP(CPI_Inflation_Data_Structured[[#This Row],[Attribute]],'Moving Average'!$A$4:$D$32,4,0) -> 167.56667 | H2256: Food & Beverages
A2257: 2020 | B2257: April | C2257: Apr-20 | D2257: Milk and products | E2257: 155.6 | F2257: 155.6 | G2257: 155.5 | H2257: Food & Beverages
A2258: 2020 | B2258: April | C2258: Apr-20 | D2258: Miscellaneous | E2258: =VLOOKUP(CPI_Inflation_Data_Structured[[#This Row],[Attribute]],'Moving Average'!$A$4:$D$32,2,0) -> 148.36667 | F2258: =VLOOKUP(CPI_Inflation_Data_Structured[[#This Row],[Attribute]],'Moving Average'!$A$4:$D$32,3,0) -> 143.6 | G2258: =VLOOKUP(CPI_Inflation_Data_Structured[[#This Row],[Attribute]],'Moving Average'!$A$4:$D$32,4,0) -> 138.5 | H2258: Other goods & services
A2259: 2020 | B2259: April | C2259: Apr-20 | D2259: Non-alcoholic beverages | E2259: 139.2 | F2259: 136.8 | G2259: 133.5 | H2259: Food & Beverages
A2260: 2020 | B2260: April | C2260: Apr-20 | D2260: Oils and fats | E2260: 137.1 | F2260: 135.1 | G2260: 131.6 | H2260: Food & Beverages
A2261: 2020 | B2261: April | C2261: Apr-20 | D2261: Pan, tobacco and intoxicants | E2261: =VLOOKUP(CPI_Inflation_Data_Structured[[#This Row],[Attribute]],'Moving Average'!$A$4:$D$32,2,0) -> 169.5 | F2261: =VLOOKUP(CPI_Inflation_Data_Structured[[#This Row],[Attribute]],'Moving Average'!$A$4:$D$32,3,0) -> 170.16667 | G2261: =VLOOKUP(CPI_Inflation_Data_Structured[[#This Row],[Attribute]],'Moving Average'!$A$4:$D$32,4,0) -> 172.03333 | H2261: Other goods & services
A2262: 2020 | B2262: April | C2262: Apr-20 | D2262: Personal care and effects | E2262: =VLOOKUP(CPI_Inflation_Data_Structured[[#This Row],[Attribute]],'Moving Average'!$A$4:$D$32,2,0) -> 143.66667 | F2262: =VLOOKUP(CPI_Inflation_Data_Structured[[#This Row],[Attribute]],'Moving Average'!$A$4:$D$32,3,0) -> 143.63333 | G2262: =VLOOKUP(CPI_Inflation_Data_Structured[[#This Row],[Attribute]],'Moving Average'!$A$4:$D$32,4,0) -> 143.63333 | H2262: Other goods & services
A2263: 2020 | B2263: April | C2263: Apr-20 | D2263: Prepared meals, snacks, sweets etc. | E2263: =VLOOKUP(CPI_Inflation_Data_Structured[[#This Row],[Attribute]],'Moving Average'!$A$4:$D$32,2,0) -> 159.3 | F2263: =VLOOKUP(CPI_Inflation_Data_Structured[[#This Row],[Attribute]],'Moving Average'!$A$4:$D$32,3,0) -> 159.1 | G2263: =VLOOKUP(CPI_Inflation_Data_Structured[[#This Row],[Attribute]],'Moving Average'!$A$4:$D$32,4,0) -> 158.86667 | H2263: Food & Beverages
A2264: 2020 | B2264: April | C2264: Apr-20 | D2264: Pulses and products | E2264: 150.2 | F2264: 150.4 | G2264: 150.8 | H2264: Food & Beverages
A2265: 2020 | B2265: April | C2265: Apr-20 | D2265: Recreation and amusement | E2265: =VLOOKUP(CPI_Inflation_Data_Structured[[#This Row],[Attribute]],'Moving Average'!$A$4:$D$32,2,0) -> 150.56667 | F2265: =VLOOKUP(CPI_Inflation_Data_Structured[[#This Row],[Attribute]],'Moving Average'!$A$4:$D$32,3,0) -> 143.23333 | G2265: =VLOOKUP(CPI_Inflation_Data_Structured[[#This Row],[Attribute]],'Moving Average'!$A$4:$D$32,4,0) -> 137.6 | H2265: Recreation
A2266: 2020 | B2266: April | C2266: Apr-20 | D2266: Spices | E2266: 158.7 | F2266: 157.1 | G2266: 154 | H2266: Food & Beverages
A2267: 2020 | B2267: April | C2267: Apr-20 | D2267: Sugar and Confectionery | E2267: 119.8 | F2267: 120.3 | G2267: 121.2 | H2267: Food & Beverages
A2268: 2020 | B2268: April | C2268: Apr-20 | D2268: Transport and communication | E2268: =VLOOKUP(CPI_Inflation_Data_Structured[[#This Row],[Attribute]],'Moving Average'!$A$4:$D$32,2,0) -> 136.03333 | F2268: =VLOOKUP(CPI_Inflation_Data_Structured[[#This Row],[Attribute]],'Moving Average'!$A$4:$D$32,3,0) -> 130.36667 | G2268: =VLOOKUP(CPI_Inflation_Data_Structured[[#This Row],[Attribute]],'Moving Average'!$A$4:$D$32,4,0) -> 125.3 | H2268: Transport
A2269: 2020 | B2269: April | C2269: Apr-20 | D2269: Vegetables | E2269: 162.7 | F2269: 168.6 | G2269: 180 | H2269: Food & Beverages
...

Sheet Data_Imputed
A1: Year | B1: Month | C1: Period | D1: Attribute | E1: Rural | F1: Rural+Urban | G1: Urban | H1: Category | K1: Year | L1: Month | M1: Period | N1: Attribute | O1: Category | P1: Sector | Q1: CPI
A2: 2013 | B2: April | C2: Apr-13 | D2: Cereals and products | E2: 110.2 | F2: 111.6 | G2: 114.6 | H2: Food & Beverages | K2: 2013 | L2: April | M2: Apr-13 | N2: Cereals and products | O2: Food & Beverages | P2: Rural | Q2: 110.2
A3: 2013 | B3: August | C3: Aug-13 | D3: Cereals and products | E3: 114.3 | F3: 115.6 | G3: 118.3 | H3: Food & Beverages | K3: 2013 | L3: April | M3: Apr-13 | N3: Cereals and products | O3: Food & Beverages | P3: Rural+Urban | Q3: 111.6
A4: 2013 | B4: April | C4: Apr-13 | D4: Clothing | E4: 108.1 | F4: 108 | G4: 107.9 | H4: Apparel | K4: 2013 | L4: April | M4: Apr-13 | N4: Cereals and products | O4: Food & Beverages | P4: Urban | Q4: 114.6
A5: 2013 | B5: April | C5: Apr-13 | D5: Meat and fish | E5: 109.5 | F5: 110.9 | G5: 113.4 | H5: Food & Beverages | K5: 2013 | L5: August | M5: Aug-13 | N5: Cereals and products | O5: Food & Beverages | P5: Rural | Q5: 114.3
A6: 2013 | B6: April | C6: Apr-13 | D6: Clothing and footwear | E6: 108 | F6: 107.9 | G6: 107.7 | H6: Apparel | K6: 2013 | L6: August | M6: Aug-13 | N6: Cereals and products | O6: Food & Beverages | P6: Rural+Urban | Q6: 115.6
A7: 2013 | B7: April | C7: Apr-13 | D7: Egg | E7: 106.9 | F7: 106.6 | G7: 106 | H7: Food & Beverages | K7: 2013 | L7: August | M7: Aug-13 | N7: Cereals and products | O7: Food & Beverages | P7: Urban | Q7: 118.3
A8: 2013 | B8: April | C8: Apr-13 | D8: Education | E8: 104.8 | F8: 105 | G8: 105.2 | H8: Education | K8: 2013 | L8: April | M8: Apr-13 | N8: Clothing | O8: Apparel | P8: Rural | Q8: 108.1
A9: 2013 | B9: April | C9: Apr-13 | D9: Milk and products | E9: 106.3 | F9: 105.7 | G9: 104.7 | H9: Food & Beverages | K9: 2013 | L9: April | M9: Apr-13 | N9: Clothing | O9: Apparel | P9: Rural+Urban | Q9: 108
A10: 2013 | B10: April | C10: Apr-13 | D10: Oils and fats | E10: 105.7 | F10: 104.4 | G10: 102.1 | H10: Food & Beverages | K10: 2013 | L10: April | M10: Apr-13 | N10: Clothing | O10: Apparel | P10: Urban | Q10: 107.9
A11: 2013 | B11: April | C11: Apr-13 | D11: Food and beverages | E11: 107.1 | F11: 107.7 | G11: 108.8 | H11: Food & Beverages | K11: 2013 | L11: April | M11: Apr-13 | N11: Meat and fish | O11: Food & Beverages | P11: Rural | Q11: 109.5
A12: 2013 | B12: April | C12: Apr-13 | D12: Fruits | E12: 108.3 | F12: 108.9 | G12: 109.5 | H12: Food & Beverages | K12: 2013 | L12: April | M12: Apr-13 | N12: Meat and fish | O12: Food & Beverages | P12: Rural+Urban | Q12: 110.9
A13: 2013 | B13: April | C13: Apr-13 | D13: Footwear | E13: 107.4 | F13: 107 | G13: 106.4 | H13: Apparel | K13: 2013 | L13: April | M13: Apr-13 | N13: Meat and fish | O13: Food & Beverages | P13: Urban | Q13: 113.4
... A3349: 2023 | B3349: May | C3349: May-23 | D3349: Vegetables | E3349: 148.7 | F3349: 161 | G3349: 185 | H3349: Food & Beverages | K3349: 2016 | L3349: July | M3349: Jul-16 | N3349: Fuel and light | O3349: Energy | P3349: Urban | Q3349: 115.5
K3350: 2016 | L3350: July | M3350: Jul-16 | N3350: General index | O3350: General Index | P3350: Rural | Q3350: 133
K3351: 2016 | L3351: July | M3351: Jul-16 | N3351: General index | O3351: General Index | P3351: Rural+Urban | Q3351: 131.1
K3352: 2016 | L3352: July | M3352: Jul-16 | N3352: General index | O3352: General Index | P3352: Urban | Q3352: 129
K3353: 2016 | L3353: July | M3353: Jul-16 | N3353: Health | O3353: Health | P3353: Rural | Q3353: 126.7
K3354: 2016 | L3354: July | M3354: Jul-16 | N3354: Health | O3354: Health | P3354: Rural+Urban | Q3354: 124.5
K3355: 2016 | L3355: July | M3355: Jul-16 | N3355: Health | O3355: Health | P3355: Urban | Q3355: 120.9
K3356: 2016 | L3356: July | M3356: Jul-16 | N3356: Household goods and services | O3356: Housing | P3356: Rural | Q3356: 130
K3357: 2016 | L3357: July | M3357: Jul-16 | N3357: Household goods and services | O3357: Housing | P3357: Rural+Urban | Q3357: 126.9
K3358: 2016 | L3358: July | M3358: Jul-16 | N3358: Household goods and services | O3358: Housing | P3358: Urban | Q3358: 123.5
K3359: 2016 | L3359: July | M3359: Jul-16 | N3359: Housing | O3359: Housing | P3359: Rural | Q3359: 0
K3360: 2016 | L3360: July | M3360: Jul-16 | N3360: Housing | O3360: Housing | P3360: Rural+Urban | Q3360: 126.4
K3361: 2016 | L3361: July | M3361: Jul-16 | N3361: Housing | O3361: Housing | P3361: Urban | Q3361: 126.4
... K10045: 2023 | L10045: May | M10045: May-23 | N10045: Vegetables | O10045: Food & Beverages | P10045: Urban | Q10045: 185

Sheet Moving Average
A1: Year | B1: 2020 | F1: Year | G1: 2020
A2: Month | B2: (Multiple Items) | F2: Month | G2: (Multiple Items)
A3: Jan to Mar | F3: Feb to Apr
A4: Row Labels | B4: Average of Rural | C4: Average of Rural+Urban | D4: Average of Urban | F4: Row Labels | G4: Average of Rural | H4: Average of Rural+Urban | I4: Average of Urban
A5: Cereals and products | B5: 144.1 | C5: 144.73333 | D5: 146.1 | F5: Cereals and products | G5: 145.26667 | H5: 146.2 | I5: 148.16667
A6: Clothing | B6: 153.06667 | C6: 150.83333 | D6: 147.33333 | F6: Clothing | G6: 153.15556 | H6: 149.77778 | I6: 148.61111
A7: Clothing and footwear | B7: 152.3 | C7: 149.5 | D7: 145.23333 | F7: Clothing and footwear | G7: 152.36667 | H7: 148.17778 | I7: 146.76667
A8: Education | B8: 161.6 | C8: 156.13333 | D8: 152.26667 | F8: Education | G8: 161.56667 | H8: 154.85556 | I8: 153.61111
A9: Egg | B9: 150.66667 | C9: 151.6 | D9: 153 | F9: Egg | G9: 148.46667 | H9: 149.56667 | I9: 151.3
A10: Food and beverages | B10: 150.33333 | C10: 150.96667 | D10: 152.06667 | F10: Food and beverages | G10: 149.36667 | H10: 150.26667 | I10: 151.76667
A11: Footwear | B11: 147.5 | C11: 141.7 | D11: 133.5 | F11: Footwear | G11: 147.53333 | H11: 139.03333 | I11: 136.33333
A12: Fruits | B12: 141.56667 | C12: 142.5 | D12: 143.6 | F12: Fruits | G12: 143.26667 | H12: 144.73333 | I12: 146.43333
A13: Fuel and light | B13: 152.03333 | C13: 146.9 | D13: 138.46667 | F13: Fuel and light | G13: 151.36667 | H13: 146.73333 | I13: 139.13333
A14: General index | B14: 150.7 | C14: 149.3 | D14: 147.73333 | F14: General index | G14: 150.3 | H14: 148.47778 | I14: 148.1
A15: Health | B15: 156.2 | C15: 151.73333 | D15: 144.4 | F15: Health | G15: 155.73333 | H15: 151.56667 | I15: 144.73333
A16: Household goods and services | B16: 151.66667 | C16: 146.33333 | D16: 140.43333 | F16: Household goods and services | G16: 151.65556 | H16: 144.41111 | I16: 142.51111
... A32: Grand Total | B32: 143.98272 | C32: 147.91235 | D32: 145.96296 | F32: Grand Total | G32: 143.99588 | H32: 147.55062 | I32: 146.79136

Sheet CrudeOil_prices
A1: Year | B1: Attribute | C1: Value
A2: 2020-21 | B2: January | C2: 54.79
A3: 2020-21 | B3: February | C3: 61.22
A4: 2020-21 | B4: March | C4: 64.73
A5: 2021-22 | B5: April | C5: 63.4
A6: 2021-22 | B6: May | C6: 66.95
A7: 2021-22 | B7: June | C7: 71.98
A8: 2021-22 | B8: July | C8: 73.54
A9: 2021-22 | B9: August | C9: 69.8
A10: 2021-22 | B10: September | C10: 73.13
A11: 2021-22 | B11: October | C11: 82.11
A12: 2021-22 | B12: November | C12: 80.64
A13: 2021-22 | B13: December | C13: 73.3
... A30: 2023-24 | B30: May | C30: 74.98

Sheet PivotTables
A2: % Contribution of each category in CPI (Latest Month- May-23) | F2: Category-wise Inflation- Year: 2021 | J2: Y-o-Y % Change in Inflation (Rural+Urban Sector) | Q2: M-o-M Analysis: Category-wise[Period: 2021-23]
A3: Period | B3: May-23 | F3: Sector | G3: Rural+Urban | J3: Sector | K3: Rural+Urban | Q3: Average of CPI | R3: Year | S3: Month | T3: Period
R4: 2020 | S4: 2021 | AE4: 2022 | AQ4: 2023
A5: Average of CPI | B5: Sector | F5: Average of CPI | G5: Year | J5: Year | K5: Average of CPI | R5: December | S5: January | T5: February | U5: March | V5: April | W5: May | X5: June | Y5: July | Z5: August | AA5: September | AB5: October | AC5: November | AD5: December | AE5: January | AF5: February | AG5: March | AH5: April | AI5: May | AJ5: June | AK5: July | AL5: August | AM5: September | AN5: October | AO5: November | AP5: December | AQ5: January | AR5: February | AS5: March | AT5: April | AU5: May
A6: Category | B6: Rural+Urban | C6: Rural | D6: Urban | F6: Category | G6: 2020 | H6: 2021 | J6: 2016 | K6: 129.80432 | Q6: Category | R6: Dec-20 | S6: Jan-21 | T6: Feb-21 | U6: Mar-21 | V6: Apr-21 | W6: May-21 | X6: Jun-21 | Y6: Jul-21 | Z6: Aug-21 | AA6: Sep-21 | AB6: Oct-21 | AC6: Nov-21 | AD6: Dec-21 | AE6: Jan-22 | AF6: Feb-22 | AG6: Mar-22 | AH6: Apr-22 | AI6: May-22 | AJ6: Jun-22 | AK6: Jul-22 | AL6: Aug-22 | AM6: Sep-22 | AN6: Oct-22 | AO6: Nov-22 | AP6: Dec-22 | AQ6: Jan-23 | AR6: Feb-23 | AS6: Mar-23 | AT6: Apr-23 | AU6: May-23
A7: Apparel | B7: 184.4 | C7: 189.96667 | D7: 176.23333 | F7: Apparel | G7: 148.78395 | H7: 158.50833 | J7: 2017 | K7: 133.4037 | Q7: Energy | R7: 144.6 | S7: 147.9 | T7: 152.4 | U7: 155.5 | V7: 155.6 | W7: 159.4 | X7: 159.8 | Y7: 160.7 | Z7: 162.6 | AA7: 162.6 | AB7: 164.2 | AC7: 163.9 | AD7: 164.1 | AE7: 164.2 | AF7: 165.7 | AG7: 167.2 | AH7: 172.2 | AI7: 174.6 | AJ7: 176 | AK7: 179.6 | AL7: 178.8 | AM7: 179.5 | AN7: 180.5 | AO7: 181.3 | AP7: 182 | AQ7: 182 | AR7: 182.1 | AS7: 181.9 | AT7: 181.7 | AU7: 182.8
A8: Education | B8: 177.1 | C8: 180.3 | D8: 174.8 | F8: Education | G8: 157.05741 | H8: 162.11667 | J8: 2018 | K8: 137.85741 | Q8: Apparel | R8: 151.33333 | S8: 151.93333 | T8: 153.46667 | U8: 154.03333 | V8: 154.86667 | W8: 158.1 | X8: 158.23333 | Y8: 159.1 | Z8: 161 | AA8: 161.06667 | AB8: 162.1 | AC8: 163.46667 | AD8: 164.73333 | AE8: 166.36667 | AF8: 167.6 | AG8: 169.26667 | AH8: 171.06667 | AI8: 172.86667 | AJ8: 174.33333 | AK8: 175.63333 | AL8: 176.9 | AM8: 178.36667 | AN8: 179.4 | AO8: 180.46667 | AP8: 181.33333 | AQ8: 182.1 | AR8: 183.33333 | AS8: 183.3 | AT8: 183.93333 | AU8: 184.4
A9: Energy | B9: 182.8 | C9: 182.5 | D9: 183.4 | F9: Energy | G9: 144.37778 | H9: 159.05833 | J9: 2019 | K9: 142.87071 | Q9: Education | R9: 159.4 | S9: 159.2 | T9: 159.5 | U9: 160.2 | V9: 160.3 | W9: 161.2 | X9: 161.7 | Y9: 163.2 | Z9: 163.8 | AA9: 163.7 | AB9: 163.9 | AC9: 164.3 | AD9: 164.4 | AE9: 164.7 | AF9: 165.4 | AG9: 166 | AH9: 166.9 | AI9: 167.9 | AJ9: 169 | AK9: 171.4 | AL9: 172.3 | AM9: 173.1 | AN9: 173.4 | AO9: 173.7 | AP9: 174.1 | AQ9: 174.3 | AR9: 175 | AS9: 175 | AT9: 176.4 | AU9: 177.1
A10: Food & Beverages | B10: 177.45385 | C10: 176.20769 | D10: 179.62308 | F10: Food & Beverages | G10: 152.59174 | H10: 163.07949 | J10: 2020 | K10: 151.75113 | Q10: Food & Beverages | R10: 162.23846 | S10: 159.73077 | T10: 156.86923 | U10: 156.87692 | V10: 158.77692 | W10: 161.97692 | X10: 164.14615 | Y10: 165.15385 | Z10: 164.76923 | AA10: 164.76923 | AB10: 167.34615 | AC10: 168.77692 | AD10: 167.76154 | AE10: 166.47692 | AF10: 166.24615 | AG10: 168.01538 | AH10: 170.33077 | AI10: 172.22308 | AJ10: 173.99231 | AK10: 174.33077 | AL10: 174.55385 | AM10: 175.45385 | AN10: 176.71538 | AO10: 176.67692 | AP10: 175.64615 | AQ10: 176.36154 | AR10: 175.31538 | AS10: 175.32308 | AT10: 176.12308 | AU10: 177.45385
A11: Health | B11: 185.7 | C11: 187.8 | D11: 182.2 | F11: Health | G11: 154.05556 | H11: 165.84167 | J11: 2021 | K11: 161.99444 | Q11: Health | R11: 158.3 | S11: 159.3 | T11: 161.3 | U11: 161.7 | V11: 162.3 | W11: 165.8 | X11: 166.3 | Y11: 167 | Z11: 168.4 | AA11: 168.4 | AB11: 169.1 | AC11: 169.9 | AD11: 170.6 | AE11: 171.4 | AF11: 172.2 | AG11: 173 | AH11: 174 | AI11: 174.8 | AJ11: 175.4 | AK11: 176.1 | AL11: 176.8 | AM11: 177.8 | AN11: 178.7 | AO11: 179.8 | AP11: 181.1 | AQ11: 182.3 | AR11: 184.4 | AS11: 184.4 | AT11: 185 | AU11: 185.7
A12: Housing | B12: 175.4 | C12: 89.9 | D12: 172.85 | F12: Housing | G12: 151.46296 | H12: 158.32917 | J12: 2022 | K12: 172.34352 | Q12: Housing | R12: 154.05 | S12: 153.85 | T12: 155.35 | U12: 155.55 | V12: 156.6 | W12: 158.15 | X12: 157.65 | Y12: 158.65 | Z12: 159.8 | AA12: 159.8 | AB12: 161 | AC12: 161.75 | AD12: 161.8 | AE12: 162.8 | AF12: 163.65 | AG12: 164.05 | AH12: 165.5 | AI12: 166.35 | AJ12: 166.6 | AK12: 167.6 | AL12: 168.75 | AM12: 169.5 | AN12: 170.8 | AO12: 171.6 | AP12: 171.4 | AQ12: 172.5 | AR12: 173.85 | AS12: 173.85 | AT12: 174.9 | AU12: 175.4
A13: Other goods & services | B13: 187.3 | C13: 188.1 | D13: 187.13333 | F13: Other goods & services | G13: 158.54043 | H13: 169 | J13: 2023 | K13: 177.71481 | Q13: Other goods & services | R13: 164.56667 | S13: 165.06667 | T13: 165.83333 | U13: 165.23333 | V13: 166.2 | W13: 169.1 | X13: 169.06667 | Y13: 170.1 | Z13: 170.7 | AA13: 170.7 | AB13: 171.5 | AC13: 172.16667 | AD13: 172.33333 | AE13: 172.63333 | AF13: 173.56667 | AG13: 175.16667 | AH13: 176.5 | AI13: 176.66667 | AJ13: 177.06667 | AK13: 177.56667 | AL13: 178.43333 | AM13: 178.83333 | AN13: 179.63333 | AO13: 180.53333 | AP13: 181.7 | AQ13: 183.2 | AR13: 184.86667 | AS13: 184.86667 | AT13: 186.53333 | AU13: 187.3
A14: Recreation | B14: 171.2 | C14: 173.8 | D14: 169.2 | F14: Recreation | G14: 145.58611 | H14: 155.6 | Q14: Recreation | R14: 148.5 | S14: 149.6 | T14: 151.5 | U14: 152.6 | V14: 153.2 | W14: 155.8 | X14: 154.9 | Y14: 155.3 | Z14: 157.6 | AA14: 157.7 | AB14: 158.6 | AC14: 159.8 | AD14: 160.6 | AE14: 161.2 | AF14: 162.1 | AG14: 163.3 | AH14: 164.4 | AI14: 165.1 | AJ14: 165.8 | AK14: 166.3 | AL14: 166.9 | AM14: 167.6 | AN14: 168.2 | AO14: 168.5 | AP14: 168.9 | AQ14: 169.5 | AR14: 170.3 | AS14: 170.3 | AT14: 170.7 | AU14: 171.2
A15: Transport | B15: 164.8 | C15: 169.7 | D15: 160.4 | F15: Transport | G15: 134.98056 | H15: 150.55833 | Q15: Transport | R15: 140.7 | S15: 141.9 | T15: 145.1 | U15: 146.2 | V15: 146.6 | W15: 148.9 | X15: 150.7 | Y15: 153.1 | Z15: 154 | AA15: 154 | AB15: 155.7 | AC15: 154.8 | AD15: 155.7 | AE15: 156.5 | AF15: 156.9 | AG15: 157.9 | AH15: 162.6 | AI15: 163 | AJ15: 161.1 | AK15: 161.6 | AL15: 161.9 | AM15: 162.3 | AN15: 162.9 | AO15: 163 | AP15: 163.4 | AQ15: 163.6 | AR15: 164.2 | AS15: 164.2 | AT15: 164.5 | AU15: 164.8
A16: General Index | B16: 179.1 | C16: 179.8 | D16: 178.2 | Q16: General Index | R16: 158.9 | S16: 157.3 | T16: 156.6 | U16: 156.8 | V16: 157.8 | W16: 160.4 | X16: 161.3 | Y16: 162.5 | Z16: 163.2 | AA16: 163.2 | AB16: 165.5 | AC16: 166.7 | AD16: 166.2 | AE16: 165.7 | AF16: 166.1 | AG16: 167.7 | AH16: 170.1 | AI16: 171.7 | AJ16: 172.6 | AK16: 173.4 | AL16: 174.3 | AM16: 175.3 | AN16: 176.7 | AO16: 176.5 | AP16: 175.7 | AQ16: 176.5 | AR16: 177.2 | AS16: 177.2 | AT16: 178.1 | AU16: 179.1
A21: M-o-M Change- Food & Beverages Category | Q21: Impact of Covid-19 Pandemic (Y-o-Y Analysis) | Z21: Impact of Covid-19 Pandemic (M-o-M Analysis)
A22: Average of CPI | C22: Year | D22: Period | Q22: Average of CPI | R22: Year | Z22: Average of CPI | AA22: Year | AB22: Month | AC22: Period
C23: 2022 | K23: 2023 | Q23: Category | R23: 2017 | S23: 2018 | T23: 2019 | U23: 2020 | V23: 2021 | W23: 2022 | X23: 2023 | AA23: 2020
A24: Category | B24: Attribute | C24: May-22 | D24: Jun-22 | E24: Jul-22 | F24: Aug-22 | G24: Sep-22 | H24: Oct-22 | I24: Nov-22 | J24: Dec-22 | K24: Jan-23 | L24: Feb-23 | M24: Mar-23 | N24: Apr-23 | O24: May-23 | Q24: Apparel | R24: 136.77222 | S24: 143.03056 | T24: 145.59697 | U24: 148.78395 | V24: 158.50833 | W24: 174.46667 | X24: 183.41333 | AA24: January | AB24: February | AC24: March | AD24: April | AE24: May | AF24: June | AG24: July | AH24: August | AI24: September | AJ24: October | AK24: November | AL24: December
A25: Food & Beverages | B25: Cereals and products | C25: 154.1 | D25: 155 | E25: 156.5 | F25: 160.3 | G25: 163.5 | H25: 165.2 | I25: 167.4 | J25: 169.2 | K25: 173.8 | L25: 174.4 | M25: 174.4 | N25: 173.8 | O25: 173.7 | Q25: Education | R25: 136 | S25: 143.89167 | T25: 153.23636 | U25: 157.05741 | V25: 162.11667 | W25: 169.825 | X25: 175.56 | Z25: Category | AA25: Jan-20 | AB25: Feb-20 | AC25: Mar-20 | AD25: Apr-20 | AE25: May-20 | AF25: Jun-20 | AG25: Jul-20 | AH25: Aug-20 | AI25: Sep-20 | AJ25: Oct-20 | AK25: Nov-20 | AL25: Dec-20
B26: Egg | C26: 162.4 | D26: 170.8 | E26: 175.2 | F26: 169.2 | G26: 169.7 | H26: 170.9 | I26: 181.4 | J26: 190.2 | K26: 194.5 | L26: 175.2 | M26: 175.2 | N26: 169.6 | O26: 173.2 | Q26: Energy | R26: 130.50833 | S26: 139.775 | T26: 140.24545 | U26: 144.37778 | V26: 159.05833 | W26: 175.13333 | X26: 182.1 | Z26: Apparel | AA26: 147.06667 | AB26: 147.33333 | AC26: 147.63333 | AD26: 147.34444 | AE26: 145.66296 | AF26: 149.43333 | AG26: 149.43333 | AH26: 149.4 | AI26: 149.9 | AJ26: 150.2 | AK26: 150.66667 | AL26: 151.33333
B27: Food and beverages | C27: 173.3 | D27: 174.9 | E27: 175 | F27: 176.3 | G27: 177.8 | H27: 179.6 | I27: 178.3 | J27: 175.9 | K27: 176.7 | L27: 177 | M27: 177 | N27: 177.9 | O27: 179.1 | Q27: Food & Beverages | R27: 134.91859 | S27: 136.38141 | T27: 141.0049 | U27: 152.59174 | V27: 163.07949 | W27: 172.55513 | X27: 176.11538 | Z27: Education | AA27: 156.1 | AB27: 156.2 | AC27: 156.1 | AD27: 156.13333 | AE27: 154.85556 | AF27: 156.4 | AG27: 156.4 | AH27: 158.5 | AI27: 157.5 | AJ27: 158.5 | AK27: 158.6 | AL27: 159.4
B28: Fruits | C28: 171 | D28: 169.7 | E28: 174.2 | F28: 172.9 | G28: 165.7 | H28: 163.8 | I28: 160.7 | J28: 158 | K28: 158.3 | L28: 169.5 | M28: 169.5 | N28: 176.3 | O28: 172.2 | Q28: Health | R28: 129.54167 | S28: 137.58333 | T28: 147.84545 | U28: 154.05556 | V28: 165.84167 | W28: 175.925 | X28: 184.36 | Z28: Energy | AA28: 144.6 | AB28: 147.2 | AC28: 148.9 | AD28: 144.1 | AE28: 146.73333 | AF28: 141.9 | AG28: 141.9 | AH28: 143 | AI28: 142.9 | AJ28: 143.1 | AK28: 143.6 | AL28: 144.6
B29: Meat and fish | C29: 217 | D29: 219.4 | E29: 213 | F29: 206.5 | G29: 209.2 | H29: 210.9 | I29: 209.4 | J29: 209 | K29: 210.7 | L29: 207.7 | M29: 207.7 | N29: 209.3 | O29: 214.3 | Q29: Housing | R29: 132.77083 | S29: 141.20833 | T29: 147.56364 | U29: 151.46296 | V29: 158.32917 | W29: 167.38333 | X29: 174.1 | Z29: Food & Beverages | AA29: 149.26154 | AB29: 147.04615 | AC29: 145.8 | AD29: 149.93077 | AE29: 147.59316 | AF29: 151.29231 | AG29: 151.29231 | AH29: 153.47692 | AI29: 154.38462 | AJ29: 157.58462 | AK29: 161.2 | AL29: 162.23846
B30: Milk and products | C30: 164.9 | D30: 165.8 | E30: 166.6 | F30: 168.1 | G30: 169.7 | H30: 170.9 | I30: 172.3 | J30: 173.6 | K30: 174.6 | L30: 177.3 | M30: 177.3 | N30: 178.4 | O30: 179.5 | Q30: Other goods & services | R30: 132.88889 | S30: 140.49167 | T30: 147.1697 | U30: 158.54043 | V30: 169 | W30: 177.35833 | X30: 185.35333 | Z30: Health | AA30: 151.2 | AB30: 151.7 | AC30: 152.3 | AD30: 150.7 | AE30: 151.56667 | AF30: 154.4 | AG30: 154.4 | AH30: 155 | AI30: 155.6 | AJ30: 156.3 | AK30: 157.2 | AL30: 158.3
B31: Non-alcoholic beverages | C31: 167.1 | D31: 167.9 | E31: 168.4 | F31: 168.8 | G31: 169.4 | H31: 169.9 | I31: 170.4 | J31: 171 | K31: 171.4 | L31: 172.3 | M31: 172.3 | N31: 172.9 | O31: 173.4 | Q31: Recreation | R31: 126.55 | S31: 133.05833 | T31: 139.91818 | U31: 145.58611 | V31: 155.6 | W31: 165.69167 | X31: 170.4 | Z31: Housing | AA31: 150.05 | AB31: 150.6 | AC31: 150.45 | AD31: 150.96667 | AE31: 149.68889 | AF31: 150.55 | AG31: 150.55 | AH31: 151.95 | AI31: 152.5 | AJ31: 152.6 | AK31: 153.6 | AL31: 154.05
B32: Oils and fats | C32: 202.4 | D32: 200.9 | E32: 195.8 | F32: 192.4 | G32: 188.7 | H32: 186.5 | I32: 188.9 | J32: 188.5 | K32: 187.2 | L32: 179.3 | M32: 179.2 | N32: 174.9 | O32: 170 | Q32: Transport | R32: 117.33333 | S32: 123.125 | T32: 125.59091 | U32: 134.98056 | V32: 150.55833 | W32: 161.09167 | X32: 164.26 | Z32: Other goods & services | AA32: 151.63333 | AB32: 152.36667 | AC32: 153.4 | AD32: 152.46667 | AE32: 152.38519 | AF32: 160.7 | AG32: 160.7 | AH32: 161.96667 | AI32: 164.26667 | AJ32: 163.9 | AK32: 164.13333 | AL32: 164.56667
B33: Prepared meals, snacks, sweets etc. | C33: 182.5 | D33: 183.9 | E33: 185.2 | F33: 186.3 | G33: 187.4 | H33: 188.3 | I33: 189.5 | J33: 190.3 | K33: 191.2 | L33: 193 | M33: 193 | N33: 193.5 | O33: 194.2 | Q33: General Index | R33: 133.5 | S33: 138.775 | T33: 144.18182 | U33: 152.63148 | V33: 161.45833 | W33: 172.15 | X33: 177.62 | Z33: Recreation | AA33: 142.8 | AB33: 143.2 | AC33: 143.7 | AD33: 143.23333 | AE33: 141.5 | AF33: 148.3 | AG33: 148.3 | AH33: 146 | AI33: 146.6 | AJ33: 146.5 | AK33: 148.4 | AL33: 148.5
B34: Pulses and products | C34: 164.7 | D34: 164.3 | E34: 164.3 | F34: 167.2 | G34: 169.1 | H34: 169.8 | I34: 170.5 | J34: 170.8 | K34: 170.9 | L34: 171 | M34: 171.1 | N34: 173.4 | O34: 175.6 | Z34: Transport | AA34: 130.9 | AB34: 130.3 | AC34: 129.9 | AD34: 130.36667 | AE34: 128.5 | AF34: 135 | AG34: 135 | AH34: 138.5 | AI34: 139.6 | AJ34: 140.6 | AK34: 140.4 | AL34: 140.7
B35: Spices | C35: 184.9 | D35: 187.1 | E35: 190 | F35: 193.6 | G35: 197.3 | H35: 199.9 | I35: 202.8 | J35: 205.2 | K35: 208.4 | L35: 209.7 | M35: 209.7 | N35: 212.9 | O35: 218 | Z35: General Index | AA35: 150.2 | AB35: 149.1 | AC35: 148.6 | AD35: 149.3 | AE35: 148.47778 | AF35: 151.8 | AG35: 151.8 | AH35: 153.9 | AI35: 154.7 | AJ35: 156.4 | AK35: 158.4 | AL35: 158.9
B36: Sugar and Confectionery | C36: 119.7 | D36: 119.9 | E36: 120 | F36: 120.9 | G36: 121.6 | H36: 121.9 | I36: 122.1 | J36: 121.8 | K36: 121.1 | L36: 120 | M36: 120 | N36: 121.3 | O36: 122.7
B37: Vegetables | C37: 174.9 | D37: 182.3 | E37: 182.1 | F37: 186.7 | G37: 191.8 | H37: 199.7 | I37: 183.1 | J37: 159.9 | K37: 153.9 | L37: 152.7 | M37: 152.8 | N37: 155.4 | O37: 161
A38: Food & Beverages Total | C38: 172.22308 | D38: 173.99231 | E38: 174.33077 | F38: 174.55385 | G38: 175.45385 | H38: 176.71538 | I38: 176.67692 | J38: 175.64615 | K38: 176.36154 | L38: 175.31538 | M38: 175.32308 | N38: 176.12308 | O38: 177.45385
A41: Y-o-Y General Index CPI Trend Analysis
A42: Category | B42: General Index
A44: Average of CPI | B44: Sector
A45: Year | B45: Rural | C45: Urban | D45: Rural+Urban
A46: 2013 | B46: 110.4 | C46: 109.60833 | D46: 110.03333
A47: 2014 | B47: 117.89167 | C47: 116.74167 | D47: 117.35
A48: 2015 | B48: 124.30833 | C48: 121.69167 | D48: 123.10833
...

Sheet Analysis
A1: INDIA CPI INFLATION & TREND ANALYSIS
A4: =PivotTables!A2 -> % Contribution of each category in CPI (Latest Month- May-23) | G4: =PivotTables!A21 -> M-o-M Change- Food & Beverages Category
A5: Category | B5: Contribution | C5: =PivotTables!B6 -> Rural+Urban | G5: Component | H5: =PivotTables!D24 -> Jun-22 | I5: =PivotTables!E24 -> Jul-22 | J5: =PivotTables!F24 -> Aug-22 | K5: =PivotTables!G24 -> Sep-22 | L5: =PivotTables!H24 -> Oct-22 | M5: =PivotTables!I24 -> Nov-22 | N5: =PivotTables!J24 -> Dec-22 | O5: =PivotTables!K24 -> Jan-23 | ... S5: =PivotTables!O24 -> May-23
A6: Apparel | B6: =(C6/$C$15) -> 0.11480843 | C6: =PivotTables!B7 -> 184.4 | G6: Cereals and products | H6: =ABS((PivotTables!D25-PivotTables!C25)/PivotTables!C25) -> 0.0058403634 | I6: =ABS((PivotTables!E25-PivotTables!D25)/PivotTables!D25) -> 0.0096774194 | J6: =ABS((PivotTables!F25-PivotTables!E25)/PivotTables!E25) -> 0.02428115 | K6: =ABS((PivotTables!G25-PivotTables!F25)/PivotTables!F25) -> 0.01996257 | L6: =ABS((PivotTables!H25-PivotTables!G25)/PivotTables!G25) -> 0.010397554 | M6: =ABS((PivotTables!I25-PivotTables!H25)/PivotTables!H25) -> 0.013317191 | N6: =ABS((PivotTables!J25-PivotTables!I25)/PivotTables!I25) -> 0.010752688 | O6: =ABS((PivotTables!K25-PivotTables!J25)/PivotTables!J25) -> 0.027186761 | ... S6: =ABS((PivotTables!O25-PivotTables!N25)/PivotTables!N25) -> 0.00057537399
A7: Education | B7: =(C7/$C$15) -> 0.11026341 | C7: =PivotTables!B8 -> 177.1 | G7: Egg | H7: =ABS((PivotTables!D26-PivotTables!C26)/PivotTables!C26) -> 0.051724138 | I7: =ABS((PivotTables!E26-PivotTables!D26)/PivotTables!D26) -> 0.025761124 | J7: =ABS((PivotTables!F26-PivotTables!E26)/PivotTables!E26) -> 0.034246575 | K7: =ABS((PivotTables!G26-PivotTables!F26)/PivotTables!F26) -> 0.0029550827 | L7: =ABS((PivotTables!H26-PivotTables!G26)/PivotTables!G26) -> 0.0070713023 | M7: =ABS((PivotTables!I26-PivotTables!H26)/PivotTables!H26) -> 0.061439438 | N7: =ABS((PivotTables!J26-PivotTables!I26)/PivotTables!I26) -> 0.048511577 | O7: =ABS((PivotTables!K26-PivotTables!J26)/PivotTables!J26) -> 0.022607781 | ... S7: =ABS((PivotTables!O26-PivotTables!N26)/PivotTables!N26) -> 0.021226415
A8: Energy | B8: =(C8/$C$15) -> 0.11381226 | C8: =PivotTables!B9 -> 182.8 | G8: Food and beverages | H8: =ABS((PivotTables!D27-PivotTables!C27)/PivotTables!C27) -> 0.0092325447 | I8: =ABS((PivotTables!E27-PivotTables!D27)/PivotTables!D27) -> 0.00057175529 | J8: =ABS((PivotTables!F27-PivotTables!E27)/PivotTables!E27) -> 0.0074285714 | K8: =ABS((PivotTables!G27-PivotTables!F27)/PivotTables!F27) -> 0.0085082246 | L8: =ABS((PivotTables!H27-PivotTables!G27)/PivotTables!G27) -> 0.010123735 | M8: =ABS((PivotTables!I27-PivotTables!H27)/PivotTables!H27) -> 0.0072383073 | N8: =ABS((PivotTables!J27-PivotTables!I27)/PivotTables!I27) -> 0.01346046 | O8: =ABS((PivotTables!K27-PivotTables!J27)/PivotTables!J27) -> 0.0045480387 | ... S8: =ABS((PivotTables!O27-PivotTables!N27)/PivotTables!N27) -> 0.0067453626
A9: Food & Beverages | B9: =(C9/$C$15) -> 0.11048372 | C9: =PivotTables!B10 -> 177.45385 | G9: Fruits | H9: =ABS((PivotTables!D28-PivotTables!C28)/PivotTables!C28) -> 0.0076023392 | I9: =ABS((PivotTables!E28-PivotTables!D28)/PivotTables!D28) -> 0.026517384 | J9: =ABS((PivotTables!F28-PivotTables!E28)/PivotTables!E28) -> 0.0074626866 | K9: =ABS((PivotTables!G28-PivotTables!F28)/PivotTables!F28) -> 0.041642568 | L9: =ABS((PivotTables!H28-PivotTables!G28)/PivotTables!G28) -> 0.011466506 | M9: =ABS((PivotTables!I28-PivotTables!H28)/PivotTables!H28) -> 0.018925519 | N9: =ABS((PivotTables!J28-PivotTables!I28)/PivotTables!I28) -> 0.016801493 | O9: =ABS((PivotTables!K28-PivotTables!J28)/PivotTables!J28) -> 0.0018987342 | ... S9: =ABS((PivotTables!O28-PivotTables!N28)/PivotTables!N28) -> 0.023255814
A10: Health | B10: =(C10/$C$15) -> 0.11561782 | C10: =PivotTables!B11 -> 185.7 | G10: Meat and fish | H10: =ABS((PivotTables!D29-PivotTables!C29)/PivotTables!C29) -> 0.011059908 | I10: =ABS((PivotTables!E29-PivotTables!D29)/PivotTables!D29) -> 0.029170465 | J10: =ABS((PivotTables!F29-PivotTables!E29)/PivotTables!E29) -> 0.030516432 | K10: =ABS((PivotTables!G29-PivotTables!F29)/PivotTables!F29) -> 0.013075061 | L10: =ABS((PivotTables!H29-PivotTables!G29)/PivotTables!G29) -> 0.008126195 | M10: =ABS((PivotTables!I29-PivotTables!H29)/PivotTables!H29) -> 0.0071123755 | N10: =ABS((PivotTables!J29-PivotTables!I29)/PivotTables!I29) -> 0.0019102197 | O10: =ABS((PivotTables!K29-PivotTables!J29)/PivotTables!J29) -> 0.0081339713 | ... S10: =ABS((PivotTables!O29-PivotTables!N29)/PivotTables!N29) -> 0.023889154
A11: Housing | B11: =(C11/$C$15) -> 0.10920498 | C11: =PivotTables!B12 -> 175.4 | G11: Milk and products | H11: =ABS((PivotTables!D30-PivotTables!C30)/PivotTables!C30) -> 0.0054578532 | I11: =ABS((PivotTables!E30-PivotTables!D30)/PivotTables!D30) -> 0.0048250905 | J11: =ABS((PivotTables!F30-PivotTables!E30)/PivotTables!E30) -> 0.0090036014 | K11: =ABS((PivotTables!G30-PivotTables!F30)/PivotTables!F30) -> 0.009518144 | L11: =ABS((PivotTables!H30-PivotTables!G30)/PivotTables!G30) -> 0.0070713023 | M11: =ABS((PivotTables!I30-PivotTables!H30)/PivotTables!H30) -> 0.0081919251 | N11: =ABS((PivotTables!J30-PivotTables!I30)/PivotTables!I30) -> 0.0075449797 | O11: =ABS((PivotTables!K30-PivotTables!J30)/PivotTables!J30) -> 0.0057603687 | ... S11: =ABS((PivotTables!O30-PivotTables!N30)/PivotTables!N30) -> 0.0061659193
A12: Other goods & services | B12: =(C12/$C$15) -> 0.11661398 | C12: =PivotTables!B13 -> 187.3 | G12: Non-alcoholic beverages | H12: =ABS((PivotTables!D31-PivotTables!C31)/PivotTables!C31) -> 0.0047875524 | I12: =ABS((PivotTables!E31-PivotTables!D31)/PivotTables!D31) -> 0.0029779631 | J12: =ABS((PivotTables!F31-PivotTables!E31)/PivotTables!E31) -> 0.0023752969 | K12: =ABS((PivotTables!G31-PivotTables!F31)/PivotTables!F31) -> 0.0035545024 | L12: =ABS((PivotTables!H31-PivotTables!G31)/PivotTables!G31) -> 0.0029515939 | M12: =ABS((PivotTables!I31-PivotTables!H31)/PivotTables!H31) -> 0.0029429076 | N12: =ABS((PivotTables!J31-PivotTables!I31)/PivotTables!I31) -> 0.0035211268 | O12: =ABS((PivotTables!K31-PivotTables!J31)/PivotTables!J31) -> 0.0023391813 | ... S12: =ABS((PivotTables!O31-PivotTables!N31)/PivotTables!N31) -> 0.002891845
A13: Recreation | B13: =(C13/$C$15) -> 0.10659004 | C13: =PivotTables!B14 -> 171.2 | G13: Oils and fats | H13: =ABS((PivotTables!D32-PivotTables!C32)/PivotTables!C32) -> 0.0074110672 | I13: =ABS((PivotTables!E32-PivotTables!D32)/PivotTables!D32) -> 0.025385764 | J13: =ABS((PivotTables!F32-PivotTables!E32)/PivotTables!E32) -> 0.017364658 | K13: =ABS((PivotTables!G32-PivotTables!F32)/PivotTables!F32) -> 0.019230769 | L13: =ABS((PivotTables!H32-PivotTables!G32)/PivotTables!G32) -> 0.011658718 | M13: =ABS((PivotTables!I32-PivotTables!H32)/PivotTables!H32) -> 0.012868633 | N13: =ABS((PivotTables!J32-PivotTables!I32)/PivotTables!I32) -> 0.0021175225 | O13: =ABS((PivotTables!K32-PivotTables!J32)/PivotTables!J32) -> 0.0068965517 | ... S13: =ABS((PivotTables!O32-PivotTables!N32)/PivotTables!N32) -> 0.028016009
A14: Transport | B14: =(C14/$C$15) -> 0.10260536 | C14: =PivotTables!B15 -> 164.8 | G14: Prepared meals, snacks, sweets etc. | H14: =ABS((PivotTables!D33-PivotTables!C33)/PivotTables!C33) -> 0.0076712329 | I14: =ABS((PivotTables!E33-PivotTables!D33)/PivotTables!D33) -> 0.0070690593 | J14: =ABS((PivotTables!F33-PivotTables!E33)/PivotTables!E33) -> 0.0059395248 | K14: =ABS((PivotTables!G33-PivotTables!F33)/PivotTables!F33) -> 0.0059044552 | L14: =ABS((PivotTables!H33-PivotTables!G33)/PivotTables!G33) -> 0.0048025614 | M14: =ABS((PivotTables!I33-PivotTables!H33)/PivotTables!H33) -> 0.0063728093 | N14: =ABS((PivotTables!J33-PivotTables!I33)/PivotTables!I33) -> 0.0042216359 | O14: =ABS((PivotTables!K33-PivotTables!J33)/PivotTables!J33) -> 0.0047293747 | ... S14: =ABS((PivotTables!O33-PivotTables!N33)/PivotTables!N33) -> 0.0036175711
A15: Total | B15: =(C15/$C$15) -> 1 | C15: =SUM(C6:C14) -> 1606.1538 | G15: Pulses and products | H15: =ABS((PivotTables!D34-PivotTables!C34)/PivotTables!C34) -> 0.0024286582 | I15: =ABS((PivotTables!E34-PivotTables!D34)/PivotTables!D34) -> 0 | J15: =ABS((PivotTables!F34-PivotTables!E34)/PivotTables!E34) -> 0.017650639 | K15: =ABS((PivotTables!G34-PivotTables!F34)/PivotTables!F34) -> 0.011363636 | L15: =ABS((PivotTables!H34-PivotTables!G34)/PivotTables!G34) -> 0.0041395624 | M15: =ABS((PivotTables!I34-PivotTables!H34)/PivotTables!H34) -> 0.0041224971 | N15: =ABS((PivotTables!J34-PivotTables!I34)/PivotTables!I34) -> 0.0017595308 | O15: =ABS((PivotTables!K34-PivotTables!J34)/PivotTables!J34) -> 0.00058548009 | ... S15: =ABS((PivotTables!O34-PivotTables!N34)/PivotTables!N34) -> 0.012687428
